Failure # 1 (occurred at 2023-05-12_18-43-18)
[36mray::ImplicitFunc.train()[39m (pid=24124, ip=127.0.0.1, repr=_tune)
  File "python\ray\_raylet.pyx", line 877, in ray._raylet.execute_task
  File "python\ray\_raylet.pyx", line 881, in ray._raylet.execute_task
  File "python\ray\_raylet.pyx", line 821, in ray._raylet.execute_task.function_executor
  File "c:\Users\djbac\anaconda3\envs\torch-gpu\lib\site-packages\ray\_private\function_manager.py", line 670, in actor_method_executor
    return method(__ray_actor, *args, **kwargs)
  File "c:\Users\djbac\anaconda3\envs\torch-gpu\lib\site-packages\ray\util\tracing\tracing_helper.py", line 460, in _resume_span
    return method(self, *_args, **_kwargs)
  File "c:\Users\djbac\anaconda3\envs\torch-gpu\lib\site-packages\ray\tune\trainable\trainable.py", line 384, in train
    raise skipped from exception_cause(skipped)
  File "c:\Users\djbac\anaconda3\envs\torch-gpu\lib\site-packages\ray\tune\trainable\function_trainable.py", line 336, in entrypoint
    return self._trainable_func(
  File "c:\Users\djbac\anaconda3\envs\torch-gpu\lib\site-packages\ray\util\tracing\tracing_helper.py", line 460, in _resume_span
    return method(self, *_args, **_kwargs)
  File "c:\Users\djbac\anaconda3\envs\torch-gpu\lib\site-packages\ray\tune\trainable\function_trainable.py", line 653, in _trainable_func
    output = fn()
  File "c:\Users\djbac\anaconda3\envs\torch-gpu\lib\site-packages\ultralytics\yolo\engine\model.py", line 436, in _tune
    self.train(**config)
  File "c:\Users\djbac\anaconda3\envs\torch-gpu\lib\site-packages\ultralytics\yolo\engine\model.py", line 365, in train
    self.trainer = TASK_MAP[self.task][1](overrides=overrides, _callbacks=self.callbacks)
  File "c:\Users\djbac\anaconda3\envs\torch-gpu\lib\site-packages\ultralytics\yolo\engine\trainer.py", line 83, in __init__
    self.device = select_device(self.args.device, self.args.batch)
  File "c:\Users\djbac\anaconda3\envs\torch-gpu\lib\site-packages\ultralytics\yolo\utils\torch_utils.py", line 85, in select_device
    p = torch.cuda.get_device_properties(i)
  File "c:\Users\djbac\anaconda3\envs\torch-gpu\lib\site-packages\torch\cuda\__init__.py", line 398, in get_device_properties
    raise AssertionError("Invalid device id")
AssertionError: Invalid device id
